Workbook

Sheet 395Papers
A1: No | B1: Publication Type | C1: Authors | D1: Article Title | E1: Selected | F1: Language | G1: Source Title | H1: Publication Year | I1: 1st Screening: Topic relevance | J1: 2nd Screening: Scope check | K1: 3rd Screening: Final content check_Specific components | L1: Reason | M1: No
A2: 1 | B2: J | C2: Rodríguez-Vázquez, AI; García-Ruiz, R; Aguaded, I | D2: Education and Communication Public Policy: Discussions and Developments | E2: 0 | F2: Spanish | G2: TRIPODOS | H2: 2020 | I2: excluded | L2: Non-english | M2: 1
A3: 2 | B3: C | C3: Hauwaert, H; Ghesquière, P; Tordoir, J; Thomson, J | D3: Karaton: An Example of AI Integration Within a Literacy App | E3: 0 | F3: English | G3: COMPUTERS HELPING PEOPLE WITH SPECIAL NEEDS, ICCHP 2020, PT I | H3: 2020 | I3: excluded | L3: Not relevant to AI literacy and framework | M3: 2
A4: 3 | B4: J | C4: Tan, DAL; Lee, BC; Kasuma, SAA; Ganapathy, M | D4: Picture Superiority Effect: Using Images for Vocabulary Enhancement Among Year One Malaysian ESL Learners | E4: 0 | F4: English | G4: PERTANIKA JOURNAL OF SOCIAL SCIENCE AND HUMANITIES | H4: 2020 | I4: excluded | L4: Not relevant to AI literacy and framework | M4: 3
A5: 4 | B5: J | C5: Korepin, VN; Dorozhkin, EM; Mikhaylova, AV; Davydova, NN | D5: RETRACTED: Digital Economy and Digital Logistics as New Area of Study in Higher Education (Retracted Article) | E5: 0 | F5: English | G5: INTERNATIONAL JOURNAL OF EMERGING TECHNOLOGIES IN LEARNING | H5: 2020 | I5: excluded | L5: Not relevant to AI literacy and framework | M5: 4
A6: 5 | B6: C | C6: Kobayashi, T; Arai, K; Imai, T; Tanimoto, S; Sato, H; Kanai, A; Miyazaki, T; Tsujino, A | D6: Service-Oriented Software Design Model for Communication Robot | E6: 0 | F6: English | G6: 2020 14TH IEEE INTERNATIONAL CONFERENCE ON SERVICE-ORIENTED SYSTEM ENGINEERING (SOSE 2020) | H6: 2020 | I6: excluded | L6: Not relevant to AI literacy and framework | M6: 5
A7: 6 | B7: C | C7: Wan, XY; Zhou, XF; Ye, ZQ; Mortensen, CK; Bai, Z | D7: SmileyCluster: Supporting Accessible Machine Learning in K-12 Scientific Discovery | E7: 0 | F7: English | G7: PROCEEDINGS OF IDC 2020 | H7: 2020 | I7: excluded | L7: Not relevant to AI literacy and framework | M7: 6
A8: 7 | B8: C | C8: Long, DR; Magerko, B | D8: What is AI Literacy? Competencies and Design Considerations | E8: 1 | F8: English | G8: PROCEEDINGS OF THE 2020 CHI CONFERENCE ON HUMAN FACTORS IN COMPUTING SYSTEMS (CHI'20) | H8: 2020 | I8: Pass | J8: Pass | K8: Pass | M8: 7
A9: 8 | B9: J | C9: Ocholla, DN; Ocholla, L | D9: Readiness of academic libraries in South Africa to research, teaching and learning support in the Fourth Industrial Revolution | E9: 0 | F9: English | G9: LIBRARY MANAGEMENT | H9: 2020 | I9: excluded | L9: Not relevant to AI literacy and framework | M9: 8
A10: 9 | B10: J | C10: Calvo, D; Cano-Orón, L; Abengozar, AE | D10: Materials and assessment of literacy level for the recognition of social bots in political misinformation contexts | E10: 0 | F10: English | G10: REVISTA ICONO 14-REVISTA CIENTIFICA DE COMUNICACION Y TECNOLOGIAS | H10: 2020 | I10: Pass | J10: excluded | L10: Media literacy | M10: 9
A11: 10 | B11: J | C11: Ajayi, AI; Awopegba, OE; Adeagbo, OA; Ushie, BA | D11: Low coverage of HIV testing among adolescents and young adults in Nigeria: Implication for achieving the UNAIDS first 95 | E11: 0 | F11: English | G11: PLOS ONE | H11: 2020 | I11: excluded | L11: Not relevant to AI literacy and framework | M11: 10
A12: 11 | B12: J | C12: Robinson, SC | D12: Trust, transparency, and openness: How inclusion of cultural values shapes Nordic national public policy strategies for artificial intelligence (AI) | E12: 0 | F12: English | G12: TECHNOLOGY IN SOCIETY | H12: 2020 | I12: excluded | L12: Not relevant to AI literacy and framework | M12: 11
A13: 12 | B13: J | C13: Fitzgerald, KC; Maki, PM; Xu, YX; Jin, W; Dastgheyb, R; Williams, DW; Springer, G; Anastos, K; Gustafson, D; Spence, AB; Adimora, AA; Waldrop, D; Vance, DE; Bolivar, H; Valcour, VG; Rubin, LH | D13: Factors Predicting Detrimental Change in Declarative Memory Among Women With HIV: A Study of Heterogeneity in Cognition | E13: 0 | F13: English | G13: FRONTIERS IN PSYCHOLOGY | H13: 2020 | I13: excluded | L13: Not relevant to AI literacy and framework | M13: 12
A14: 13 | B14: J | C14: Zhexenova, Z; Amirova, A; Abdikarimova, M; Kudaibergenov, K; Baimakhan, N; Tleubayev, B; Asselborn, T; Johal, W; Dillenbourg, P; CohenMiller, A; Sandygulova, A | D14: A Comparison of Social Robot to Tablet and Teacher in a New Script Learning Context | E14: 0 | F14: English | G14: FRONTIERS IN ROBOTICS AND AI | H14: 2020 | I14: excluded | L14: Not relevant to AI literacy and framework | M14: 13
A15: 14 | B15: C | C15: Olari, V; Romeike, R | D15: Addressing AI and Data Literacy in Teacher Education: A Review of Existing Educational Frameworks | E15: 1 | F15: English | G15: PROCEEDINGS OF THE 16TH WORKSHOP IN PRIMARY AND SECONDARY COMPUTING EDUCATION, WIPSCE 2021 | H15: 2021 | I15: Pass | J15: Pass | K15: Pass | M15: 14
A16: 15 | B16: C | C16: Coetzee, C; Matthee, M | D16: Computational Numeracy (CN) for Under-Prepared, Novice Programming Students | E16: 0 | F16: English | G16: RESPONSIBLE AI AND ANALYTICS FOR AN ETHICAL AND INCLUSIVE DIGITIZED SOCIETY, I3E 2021 | H16: 2021 | I16: excluded | L16: Not relevant to AI literacy and framework | M16: 15
A17: 16 | B17: C | C17: Peinado, I; de Lera, E; Usero, JM; Clark, C; Treviranus, J; Vanderheiden, G | D17: Digital Inclusion at the Workplace Post Covid19 | E17: 0 | F17: English | G17: PROCEEDINGS OF THE 13TH INTERNATIONAL JOINT CONFERENCE ON COMPUTATIONAL INTELLIGENCE (IJCCI) | H17: 2021 | I17: excluded | L17: Not relevant to AI literacy and framework | M17: 16
A18: 17 | B18: J | C18: Ozbalci, S | D18: INCLUSIVE WORKPLACE, SOCIAL MOBILITY AND LOGISTICS | E18: 0 | F18: English | G18: LOGFORUM | H18: 2021 | I18: excluded | L18: Not relevant to AI literacy and framework | M18: 17
A19: 18 | B19: C | C19: Liu, JQ; Jung, YJ | D19: Interest Development, Knowledge Learning, and Interactive IR Toward a State-based Approach to Search as Learning | E19: 0 | F19: English | G19: CHIIR '21: PROCEEDINGS OF THE 2021 CONFERENCE ON HUMAN INFORMATION INTERACTION AND RETRIEVAL | H19: 2021 | I19: excluded | L19: Not relevant to AI literacy and framework | M19: 18
A20: 19 | B20: C | C20: Voulgari, I; Zammit, M; Stouraitis, E; Liapis, A; Yannakakis, GN | D20: Learn to Machine Learn: Designing a Game Based Approach for Teaching Machine Learning to Primary and Secondary Education Students | E20: 0 | F20: English | G20: IDC '21: PROCEEDINGS OF INTERACTION DESIGN AND CHILDREN 2021 | H20: 2021 | I20: excluded | L20: Not relevant to AI literacy and framework | M20: 19
A21: 20 | B21: J | C21: Sanchez-Acedo, A; Carbonell-Alcocer, A; Gertrudix, M; Rubio-Tamayo, JL | D21: The challenges of media and information literacy in the artificial intelligence ecology : deepfakes and misinformation | E21: 0 | F21: English | G21: COMMUNICATION & SOCIETY-SPAIN | H21: 2021 | I21: Pass | J21: excluded | L21: Media information literacy | M21: 20
A22: 21 | B22: C | C22: Zammit, M; Voulgari, I; Liapis, A; Yannakakis, G | D22: The Road to AI Literacy Education: From Pedagogical Needs to Tangible Game Design | E22: 0 | F22: English | G22: PROCEEDINGS OF THE 15TH EUROPEAN CONFERENCE ON GAME BASED LEARNING (ECGBL 2021) | H22: 2021 | I22: Pass | J22: excluded | L22: Educational game design | M22: 21
A23: 22 | B23: C | C23: Rodriguez-Ruiz, J; Alvarez-Delgado, A; Caratozzolo, P | D23: Use of Natural Language Processing (NLP) Tools to Assess Digital Literacy Skills | E23: 0 | F23: English | G23: 2021 MACHINE LEARNING-DRIVEN DIGITAL TECHNOLOGIES FOR EDUCATIONAL INNOVATION WORKSHOP | H23: 2021 | I23: Pass | J23: excluded | L23: Digital literacy | M23: 22
A24: 23 | B24: J | C24: Wienrich, C; Carolus, A | D24: Development of an Instrument to Measure Conceptualizations and Competencies About Conversational Agents on the Example of Smart Speakers | E24: 0 | F24: English | G24: FRONTIERS IN COMPUTER SCIENCE | H24: 2021 | I24: excluded | L24: Not relevant to AI literacy and framework | M24: 23
A25: 24 | B25: J | C25: Kupec, M; Jakubíková, D; Kupec, V | D25: Web Personalization And Artificial Intelligence As Tools For Marketing Communications | E25: 0 | F25: English | G25: MEDIA LITERACY AND ACADEMIC RESEARCH | H25: 2021 | I25: excluded | L25: Not relevant to AI literacy and framework | M25: 24
A26: 25 | B26: J | C26: Lee, PY; Cheong, AT; Ghazali, SS; Salim, H; Wong, J; Hussein, N; Ramli, R; Pinnock, H; Liew, SM; Hanafi, NS; Abu Bakar, AI; Ahad, AM; Pang, YK; Chinna, K; Khoo, EM | D26: Barriers to implementing asthma self-management in Malaysian primary care: qualitative study exploring the perspectives of healthcare professionals | E26: 0 | F26: English | G26: NPJ PRIMARY CARE RESPIRATORY MEDICINE | H26: 2021 | I26: excluded | L26: Not relevant to AI literacy and framework | M26: 25
A27: 26 | B27: J | C27: Cudjoe, J; Budhathoki, C; Roter, D; Gallo, JJ; Sharps, P; Han, HR | D27: Exploring Health Literacy and the Correlates of Pap Testing Among African Immigrant Women: Findings from the AfroPap Study | E27: 0 | F27: English | G27: JOURNAL OF CANCER EDUCATION | H27: 2021 | I27: Pass | J27: excluded | L27: Health literacy | M27: 26
A28: 27 | B28: J | C28: Henry, J; Hernalesteen, A; Collard, AS | D28: Teaching Artificial Intelligence to K-12 Through a Role-Playing Game Questioning the Intelligence Concept | E28: 1 | F28: English | G28: KUNSTLICHE INTELLIGENZ | H28: 2021 | I28: Pass | J28: Pass | K28: Pass | M28: 27
A29: 28 | B29: J | C29: Lee, J; Wu, ANSY; Li, D; Kulasegaram, K | D29: Artificial Intelligence in Undergraduate Medical Education: A Scoping Review | E29: 0 | F29: English | G29: ACADEMIC MEDICINE | H29: 2021 | I29: excluded | L29: Not relevant to AI literacy and framework | M29: 28
A30: 29 | B30: J | C30: Liu, TM; Xiao, X | D30: A Framework of AI-Based Approaches to Improving eHealth Literacy and Combating Infodemic | E30: 0 | F30: English | G30: FRONTIERS IN PUBLIC HEALTH | H30: 2021 | I30: Pass | J30: excluded | L30: Health literacy | M30: 29
A31: 30 | B31: J | C31: Veldkamp, SAM; Zondervan-Zwijnenburg, MAJ; van Bergen, E; Barzeva, SA; Tamayo-Martinez, N; Becht, A; van Beijsterveldt, CEM; Meeus, W; Branje, S; Hillegers, MHJ; Oldehinkel, AJ; Hoijtink, HJA; Boomsma, D; Hartman, C | D31: Parental Age in Relation to Offspring's Neurodevelopment | E31: 0 | F31: English | G31: JOURNAL OF CLINICAL CHILD AND ADOLESCENT PSYCHOLOGY | H31: 2021 | I31: excluded | L31: Not relevant to AI literacy and framework | M31: 30
A32: 31 | B32: C | C32: Liu, YX; Moore, A; Webb, J; Vallor, S | D32: Artificial Moral Advisors: A New Perspective from Moral Psychology | E32: 0 | F32: English | G32: PROCEEDINGS OF THE 2022 AAAI/ACM CONFERENCE ON AI, ETHICS, AND SOCIETY, AIES 2022 | H32: 2022 | I32: excluded | L32: Not relevant to AI literacy and framework | M32: 31
A33: 32 | B33: C | C33: Kusuma, M; Mohanty, V; Wang, M; Luther, K | D33: Civil War Twin: Exploring Ethical Challenges in Designing an Educational Face Recognition Application | E33: 0 | F33: English | G33: PROCEEDINGS OF THE 2022 AAAI/ACM CONFERENCE ON AI, ETHICS, AND SOCIETY, AIES 2022 | H33: 2022 | I33: excluded | L33: Not relevant to AI literacy and framework | M33: 32
A34: 33 | B34: C | C34: Kakeshita, T; Ishii, K; Ishikawa, Y; Matsubara, H; Matsuo, Y; Murata, T; Nakano, M; Nakatani, T; Okumura, H; Takahashi, N; Takahashi, N; Uchida, G; Uematsu, E; Saeki, S; Kato, H | D34: Development of IPSJ Data Science Curriculum Standard | E34: 0 | F34: English | G34: DIGITAL TRANSFORMATION OF EDUCATION AND LEARNING - PAST, PRESENT AND FUTURE, OCCE 2021 | H34: 2022 | I34: excluded | L34: Not relevant to AI literacy and framework | M34: 33
A35: 34 | B35: C | C35: Medaglia, R; Tangi, L | D35: The adoption of Artificial Intelligence in the public sector in Europe: drivers, features, and impacts | E35: 0 | F35: English | G35: PROCEEDINGS OF THE 15TH INTERNATIONAL CONFERENCE ON THEORY AND PRACTICE OF ELECTRONIC GOVERNANCE, ICEGOV 2022 | H35: 2022 | I35: excluded | L35: Not relevant to AI literacy and framework | M35: 34
A36: 35 | B36: C | C36: Druga, S; Otero, N; Ko, AJ | D36: The Landscape of Teaching Resources for AI Education | E36: 0 | F36: English | G36: PROCEEDINGS OF THE 27TH ACM CONFERENCE ON INNOVATION AND TECHNOLOGY IN COMPUTER SCIENCE EDUCATION, ITICSE 2022, VOL 1 | H36: 2022 | I36: excluded | L36: Not relevant to AI literacy and framework | M36: 35
A37: 36 | B37: C | C37: Perla, L; Massaro, S | D37: Virtual Patient Education Scenarios: Exploratory Step in the Study of Obesity Prevention Through Telemedicine | E37: 0 | F37: English | G37: HIGHER EDUCATION LEARNING METHODOLOGIES AND TECHNOLOGIES ONLINE, HELMETO 2021 | H37: 2022 | I37: excluded | L37: Not relevant to AI literacy and framework | M37: 36
A38: 37 | B38: C | C38: Wilton, L; Ip, S; Sharma, M; Fan, F | D38: Where Is the AI? AI Literacy for Educators | E38: 0 | F38: English | G38: ARTIFICIAL INTELLIGENCE IN EDUCATION: POSTERS AND LATE BREAKING RESULTS, WORKSHOPS AND TUTORIALS, INDUSTRY AND INNOVATION TRACKS, PRACTITIONERS AND DOCTORAL CONSORTIUM, PT II | H38: 2022 | I38: Pass | J38: excluded | L38: Reflective case study in AIED | M38: 37
A39: 38 | B39: J | C39: Hirschprung, RS; Alkoby, S | D39: A Game Theory Approach for Assisting Humans in Online Information-Sharing | E39: 0 | F39: English | G39: INFORMATION | H39: 2022 | I39: excluded | L39: Not relevant to AI literacy and framework | M39: 38
A40: 39 | B40: J | C40: Warren-Jeanpiere, L; Goparaju, L; Spence, AB; Michel, K; Wang, CW; Kikkisetti, A; Kassaye, S | D40: I Haven't Been Ill, I Know It's There: a Case Study Examination of the Social, Behavioral, Clinical, and Structural Factors that Contribute to Sustained Viremia Among Women Living with HIV | E40: 0 | F40: English | G40: JOURNAL OF RACIAL AND ETHNIC HEALTH DISPARITIES | H40: 2022 | I40: excluded | L40: Not relevant to AI literacy and framework | M40: 39
...

Sheet 41Papers
A1: Article No | B1: Article Title | C1: Framework Elements | D1: No
A2: 1 | B2: ED-AI Lit: An Interdisciplinary Framework for AI Literacy in Education | C2: Knowledge,Evaluation,Collaboration,Autonomy,Ethics | D2: =VLOOKUP(B2, '395Papers'!D$2:M$396, 10, 0) -> 258
A3: 2 | B3: A systematic review of AI literacy conceptualization, constructs, and implementation and assessment efforts (2019-2023) | C3: Recognize,Know & Understand,Use & Apply ,Evaluate, Create, Navigate Ethically | D3: =VLOOKUP(B3, '395Papers'!D$2:M$396, 10, 0) -> 244
A4: 3 | B4: Towards an educational framework for integrating AI education into second-level education in Ireland | C4: . Introduction to AI,.AI and Ethics, AI and the Future of Work, AI Careers | D4: =VLOOKUP(B4, '395Papers'!D$2:M$396, 10, 0) -> 176
A5: 4 | B5: From Gretel to Strudelcity: Empowering Teachers Regarding Generative AI for Enhanced AI Literacy with CollectiveGPT | C5: Probability, Context,Training,Manipulation | D5: =VLOOKUP(B5, '395Papers'!D$2:M$396, 10, 0) -> 346
A6: 5 | B6: AI literacy in K-12: a systematic literature review | C6: Learning to recognize artifacts using AI,Learning about how AI works,Learning tools for AI,Learning for life with AI | D6: =VLOOKUP(B6, '395Papers'!D$2:M$396, 10, 0) -> 80
A7: 6 | B7: Exploring the Determinants of Artificial Intelligence (AI) Literacy: Digital Divide, Computational Thinking, Cognitive Absorption | C7: Awareness, Usage, Evaluation, Ethics | D7: =VLOOKUP(B7, '395Papers'!D$2:M$396, 10, 0) -> 114
A8: 7 | B8: University Students' Conceptualisation of AI Literacy: Theory and Empirical Evidence | C8: A critical approach, Ethical approach, Completing specific tasks, Improving everyday life,Digital competences,Knowledge of technical basics | D8: =VLOOKUP(B8, '395Papers'!D$2:M$396, 10, 0) -> 261
A9: 8 | B9: A Competency Framework for AI Literacy: Variations by Different Learner Groups and an Implied Learning Pathway | C9: AI device and software/ application/platform operations, Data and algorithm literacy, Problem solving,Communication and collaboration, AI ethics, Career-related competences, AI content creation, Affective competences. | D9: =VLOOKUP(B9, '395Papers'!D$2:M$396, 10, 0) -> 314
A10: 9 | B10: What are artificial intelligence literacy and competency? A comprehensive framework to support them | C10: Technology,Impact ,Ethics, Collaboration ,Self-reflection | D10: =VLOOKUP(B10, '395Papers'!D$2:M$396, 10, 0) -> 253
A11: 10 | B11: Earth Science Simulations with Generative Artificial Intelligence (GenAI) | C11: Affective,Behavioural, Cognitive,Ethical | D11: =VLOOKUP(B11, '395Papers'!D$2:M$396, 10, 0) -> 318
A12: 11 | B12: Developing an AI literacy diagnostic tool for elementary school students | C12: What is AI?,What can AI do?,How does AI work?,Understanding AI as software ,How should AI be used? | D12: =VLOOKUP(B12, '395Papers'!D$2:M$396, 10, 0) -> 357
A13: 12 | B13: Constructing a STEM Projects Design Framework for Middle School AI Courses: Developing Students' AI Literacy as Project Goals | C13: Subject-Object Analysis Layer,Project Design Layer,Learning Tools Layer,Project Rules Layer,Project Goals Layer | D13: =VLOOKUP(B13, '395Papers'!D$2:M$396, 10, 0) -> 135
... A42: 41 | B42: Using the information inequity framework to study GenAI equity: analysis of educational perspectives | C42: Access,Content,Context,Skills,Values | D42: =VLOOKUP(B42, '395Papers'!D$2:M$396, 10, 0) -> 383

Sheet Framework_elements
A1: Paper No. | B1: Keywords
A2: 1 | B2: autonomy
A3: 1 | B3: collaboration
A4: 1 | B4: ethics
A5: 1 | B5: evaluation
A6: 1 | B6: knowledge
A7: 2 | B7: create
A8: 2 | B8: evaluate
A9: 2 | B9: know understand
A10: 2 | B10: navigate ethically
A11: 2 | B11: recognize
A12: 2 | B12: use apply
A13: 3 | B13: ai and ethics
... A273: 41 | B273: values

Sheet Meta
B2: ABCE_CLS_RES | C2: Count | D2: Duplications | E2: Remains | G2: ABCE_CLS_RES | H2: Count | I2: Duplications | J2: Remains | L2: ABCE_CLS_RES | M2: Affective | N2: Behavioural | O2: Cognitive | P2: Ethical | Q2: Sum
B3: Affective | C3: =COUNTIF(ABCE_Result!C$2:C$273, B3) -> 38 | D3: 1 | E3: 37 | G3: Human-centred mindset | H3: =COUNTIF(UNESCO_Result!C$2:C$273, G3) -> 43 | I3: =H3-J3 -> 0 | J3: 43 | L3: AI system design | M3: 4 | N3: 3 | O3: 14 | P3: 5 | Q3: =SUM(M3:P3) -> 26
B4: Behavioural | C4: =COUNTIF(ABCE_Result!C$2:C$273, B4) -> 30 | D4: 5 | E4: 25 | G4: Ethics of AI | H4: =COUNTIF(UNESCO_Result!C$2:C$273, G4) -> 65 | I4: =H4-J4 -> 16 | J4: 49 | L4: AI techniques and applications | M4: 12 | N4: 9 | O4: 61 | P4: 3 | Q4: =SUM(M4:P4) -> 85
B5: Cognitive | C5: =COUNTIF(ABCE_Result!C$2:C$273, B5) -> 141 | D5: 14 | E5: 127 | G5: AI techniques and applications | H5: =COUNTIF(UNESCO_Result!C$2:C$273, G5) -> 94 | I5: =H5-J5 -> 9 | J5: 85 | L5: Ethics of AI | M5: 8 | N5: 1 | O5: 15 | P5: 25 | Q5: =SUM(M5:P5) -> 49
B6: Ethical | C6: =COUNTIF(ABCE_Result!C$2:C$273, B6) -> 56 | D6: 7 | E6: 49 | G6: AI system design | H6: =COUNTIF(UNESCO_Result!C$2:C$273, G6) -> 27 | I6: =H6-J6 -> 1 | J6: 26 | L6: Human-centred mindset | M6: 8 | N6: 11 | O6: 13 | P6: 11 | Q6: =SUM(M6:P6) -> 43
B7: Others | C7: =COUNTIF(ABCE_Result!C$2:C$273, B7) -> 7 | D7: 0 | E7: 7 | G7: Others | H7: =COUNTIF(UNESCO_Result!C$2:C$273, G7) -> 43 | I7: =H7-J7 -> 2 | J7: 41 | L7: sum | M7: =SUM(M3:M6) -> 32 | N7: =SUM(N3:N6) -> 24 | O7: =SUM(O3:O6) -> 103 | P7: =SUM(P3:P6) -> 44 | Q7: =SUM(M7:P7) -> 203
B8: sum | C8: =SUM(C3:C7) -> 272 | D8: =SUM(D3:D7) -> 27 | E8: =SUM(E3:E7) -> 245 | G8: sum | H8: =SUM(H3:H7) -> 272 | I8: =SUM(I3:I7) -> 28 | J8: =SUM(J3:J7) -> 244

Sheet ABCE_CRI_KW
A1: Dimension | B1: Keyword
A2: Affective | B2: affective
A3: Affective | B3: confident and self-efficacious users who have interests and motivation to learn ai
A4: Affective | B4: confident users
A5: Affective | B5: interests
A6: Affective | B6: learn ai
A7: Affective | B7: motivation
A8: Affective | B8: self-efficacious users
A9: Affective | B9: attention
A10: Affective | B10: confidence
A11: Affective | B11: digital information literacy
A12: Affective | B12: digital information literacy in terms of attention, confidence, satisfaction, enjoyment and perceived usefulness.
... A117: Ethical | B117: reputation

Sheet ABCE_Result
A1: Paper No. | B1: Keyword | C1: BestCategory_max | D1: BestSim_max | E1: Sim_max_Affective | F1: Sim_max_Behavioural | G1: Sim_max_Cognitive | H1: Sim_max_Ethical
A2: 1 | B2: autonomy | C2: Affective | D2: 0.60716677 | E2: 0.60716677 | F2: 0.45098567 | G2: 0.45916641 | H2: 0.5674215
A3: 4 | B3: probability | C3: Affective | D3: 0.47942013 | E3: 0.47942013 | F3: 0.36195973 | G3: 0.44542614 | H3: 0.31410903
A4: 5 | B4: learning to recognize artifacts using ai | C4: Affective | D4: 0.61729574 | E4: 0.61729574 | F4: 0.54451299 | G4: 0.5731746 | H4: 0.35408571
A5: 5 | B5: learning about how ai works | C5: Affective | D5: 0.84888291 | E5: 0.84888291 | F5: 0.66174817 | G5: 0.75792092 | H5: 0.46610874
A6: 5 | B6: learning tools for ai | C6: Affective | D6: 0.82603514 | E6: 0.82603514 | F6: 0.59542549 | G6: 0.7526232 | H6: 0.4697662
A7: 5 | B7: learning for life with ai | C7: Affective | D7: 0.80094814 | E7: 0.80094814 | F7: 0.59717083 | G7: 0.62939477 | H7: 0.33563653
A8: 8 | B8: data and algorithm literacy | C8: Affective | D8: 0.68142748 | E8: 0.68142748 | F8: 0.42333224 | G8: 0.54782438 | H8: 0.44302112
A9: 8 | B9: affective competences | C9: Affective | D9: 0.69511139 | E9: 0.69511139 | F9: 0.63121724 | G9: 0.57192183 | H9: 0.61387056
A10: 9 | B10: selfreflection | C10: Affective | D10: 0.70169896 | E10: 0.70169896 | F10: 0.55207902 | G10: 0.51729661 | H10: 0.34804666
A11: 10 | B11: affective | C11: Affective | D11: 1 | E11: 1 | F11: 0.68103617 | G11: 0.50481474 | H11: 0.53446561
A12: 12 | B12: project goals layer | C12: Affective | D12: 0.42477113 | E12: 0.42477113 | F12: 0.34736335 | G12: 0.37727517 | H12: 0.34336308
A13: 18 | B13: generic ai literacy | C13: Affective | D13: 0.67091727 | E13: 0.67091727 | F13: 0.40768847 | G13: 0.48054054 | H13: 0.42074162
... A273: 32 | B273: time and chronology | C273: Others | D273: 0.34780246 | E273: 0.25820047 | F273: 0.22445847 | G273: 0.34780246 | H273: 0.26160422

Sheet UNESCO_CRI_KW
A1: Dimension | B1: Keyword
A2: Human-centred mindset | B2: human-centred mindset
A3: Human-centred mindset | B3: human agency
A4: Human-centred mindset | B4: human accountability
A5: Human-centred mindset | B5: citizenship in the era of ai
A6: Ethics of AI | B6: ethics of ai
A7: Ethics of AI | B7: embodied ethics
A8: Ethics of AI | B8: safe and responsible use
A9: Ethics of AI | B9: ethics by design
A10: AI techniques and applications | B10: ai techniques and applications
A11: AI techniques and applications | B11: ai foundations
A12: AI techniques and applications | B12: application skills
... A17: AI system design | B17: iteration and feedback loops

Sheet UNESCO_Result
A1: Article No. | B1: Keyword | C1: BestCategory_max | D1: BestSim_max | E1: Sim_max_Human-centred mindset | F1: Sim_max_Ethics of AI | G1: Sim_max_AI techniques and applications | H1: Sim_max_AI system design
A2: 36 | B2: action and reaction | C2: AI system design | D2: 0.45492941 | E2: 0.37886739 | F2: 0.32314557 | G2: 0.32386383 | H2: 0.45492941
A3: 35 | B3: action reaction | C3: AI system design | D3: 0.40517128 | E3: 0.3185516 | F3: 0.24263948 | G3: 0.27832425 | H3: 0.40517128
A4: 27 | B4: ai and the future of work | C4: AI system design | D4: 0.5727396 | E4: 0.48907116 | F4: 0.50067216 | G4: 0.56465483 | H4: 0.5727396
A5: 22 | B5: ai systems thinking | C5: AI system design | D5: 0.82615232 | E5: 0.3290056 | F5: 0.54171944 | G5: 0.65535182 | H5: 0.82615232
A6: 38 | B6: analyzing through | C6: AI system design | D6: 0.53933251 | E6: 0.34058487 | F6: 0.36553025 | G6: 0.42572913 | H6: 0.53933251
A7: 36 | B7: computational thinking | C7: AI system design | D7: 0.44125226 | E7: 0.41294515 | F7: 0.3061921 | G7: 0.37026501 | H7: 0.44125226
A8: 4 | B8: continuous evaluation and adaptation | C8: AI system design | D8: 0.50867134 | E8: 0.28543019 | F8: 0.32062542 | G8: 0.38931677 | H8: 0.50867134
A9: 36 | B9: engineering design thinking | C9: AI system design | D9: 0.76348394 | E9: 0.34554631 | F9: 0.56387854 | G9: 0.35373122 | H9: 0.76348394
A10: 22 | B10: environment digital | C10: AI system design | D10: 0.45617539 | E10: 0.26348907 | F10: 0.32774788 | G10: 0.33913058 | H10: 0.45617539
A11: 22 | B11: environment physical | C11: AI system design | D11: 0.4488017 | E11: 0.21270703 | F11: 0.31777775 | G11: 0.40163964 | H11: 0.4488017
A12: 13 | B12: evaluate | C12: AI system design | D12: 0.48099589 | E12: 0.29305547 | F12: 0.39536762 | G12: 0.39880985 | H12: 0.48099589
A13: 32 | B13: imagine future ai | C13: AI system design | D13: 0.54167342 | E13: 0.42212453 | F13: 0.46294668 | G13: 0.47740719 | H13: 0.54167342
... A273: 39 | B273: writing ethnographic vignettes | C273: Others | D273: 0.30548695 | E273: 0.30548695 | F273: 0.29868209 | G273: 0.26329204 | H273: 0.20025627

Sheet ABCE-UNESCO
A1: Article No. | B1: Keyword | C1: BestCategory_max | D1: Expert_Modified
A2: 36 | B2: action and reaction | C2: AI system design | D2: AI system design
A3: 35 | B3: action reaction | C3: AI system design | D3: AI system design
A4: 27 | B4: ai and the future of work | C4: AI system design | D4: Human-centred mindset
A5: 22 | B5: ai systems thinking | C5: AI system design | D5: AI system design
A6: 38 | B6: analyzing through | C6: AI system design | D6: AI system design
A7: 36 | B7: computational thinking | C7: AI system design | D7: AI system design
A8: 4 | B8: continuous evaluation and adaptation | C8: AI system design | D8: AI system design
A9: 36 | B9: engineering design thinking | C9: AI system design | D9: AI system design
A10: 22 | B10: environment digital | C10: AI system design | D10: AI system design
A11: 22 | B11: environment physical | C11: AI system design | D11: AI system design
A12: 13 | B12: evaluate | C12: AI system design | D12: AI system design
A13: 32 | B13: imagine future ai | C13: AI system design | D13: Human-centred mindset
... A273: 39 | B273: writing ethnographic vignettes | C273: Others | D273: Others
